<?xml version="1.0" encoding="utf-8" ?>
<!-- =================================================================================== -->
<!-- |    This document was autogenerated by xacro from /home/iman/version-control/ws_moveit_exp1/src/r_mini_description/urdf/arm_test.urdf.xacro | -->
<!-- |    EDITING THIS FILE BY HAND IS NOT RECOMMENDED                                 | -->
<!-- =================================================================================== -->
<robot name="r_mini">
    <link name="world" />
    <!--Adding more than one free link will cause error-->
    <!--link name="world_base"/-->
    <!--Loading the arm meshes and the collision meshes-->
    <link name="base_link">
        <visual>
            <geometry>
                <mesh filename="package://r_mini_description/meshes/base_link.dae" />
            </geometry>
        </visual>
        <collision>
            <origin rpy="0 0 0" xyz="0 0 0" />
            <geometry>
                <mesh filename="package://r_mini_description/meshes/base_link_collision.stl" />
            </geometry>
        </collision>
        <inertial>
            <mass value="1.8425" />
            <origin rpy="0 0 0" xyz="0 0 0.07339" />
            <inertia ixx="0.009" ixy="1.973e-6" ixz="-6.423e-6" iyy="0.009" iyz="-8.010e-6" izz="0.009" />
        </inertial>
    </link>
    <link name="link1">
        <visual>
            <geometry>
                <mesh filename="package://r_mini_description/meshes/link1.dae" />
            </geometry>
        </visual>
        <collision>
            <origin rpy="0 0 0" xyz="0 0 0" />
            <geometry>
                <mesh filename="package://r_mini_description/meshes/link1_collision.stl" />
            </geometry>
        </collision>
        <inertial>
            <mass value="0.211" />
            <origin rpy="0 0 0" xyz="0 -0.006 -0.043" />
            <inertia ixx="3.1e-4" ixy="-2.617e-12" ixz="1.423e-12" iyy="2.232e-4" iyz="6.199e-5" izz="2.489e-4" />
        </inertial>
    </link>
    <link name="link2">
        <visual>
            <geometry>
                <mesh filename="package://r_mini_description/meshes/link2.dae" />
            </geometry>
        </visual>
        <collision>
            <origin rpy="0 0 0" xyz="0 0 0" />
            <geometry>
                <mesh filename="package://r_mini_description/meshes/link2_collision.stl" />
            </geometry>
        </collision>
        <inertial>
            <mass value="0.938" />
            <origin rpy="0 0 0" xyz="-0.23 0.009 0.002" />
            <inertia ixx="0.001" ixy="-0.001" ixz="1.955e-4" iyy="0.017" iyz="1.303e-5" izz="0.017" />
        </inertial>
    </link>
    <link name="link3">
        <visual>
            <geometry>
                <mesh filename="package://r_mini_description/meshes/link3.dae" />
            </geometry>
        </visual>
        <collision>
            <origin rpy="0 0 0" xyz="0 0 0" />
            <geometry>
                <mesh filename="package://r_mini_description/meshes/link3_collision.stl" />
            </geometry>
        </collision>
        <inertial>
            <mass value="0.36" />
            <origin rpy="0 0 0" xyz="-0.042 0.058 0.001" />
            <inertia ixx="0.001" ixy="3.426e-4" ixz="-1.648e-5" iyy="0.001" iyz="2.263e-5" izz="0.001" />
        </inertial>
    </link>
    <link name="link4">
        <visual>
            <geometry>
                <mesh filename="package://r_mini_description/meshes/link4.dae" />
            </geometry>
        </visual>
        <collision>
            <origin rpy="0 0 0" xyz="0 0 0" />
            <geometry>
                <mesh filename="package://r_mini_description/meshes/link4_collision.stl" />
            </geometry>
        </collision>
        <inertial>
            <mass value="0.379" />
            <origin rpy="0 0 0" xyz="-6.199e-5 -0.033 0.279" />
            <inertia ixx="0.009" ixy="-6.824e-7" ixz="2.091e-6" iyy="0.009" iyz="0.001" izz="0.001" />
        </inertial>
    </link>
    <link name="link5">
        <visual>
            <geometry>
                <mesh filename="package://r_mini_description/meshes/link5.dae" />
            </geometry>
        </visual>
        <collision>
            <origin rpy="0 0 0" xyz="0 0 0" />
            <geometry>
                <mesh filename="package://r_mini_description/meshes/link5_collision.stl" />
            </geometry>
        </collision>
        <inertial>
            <mass value="0.207" />
            <origin rpy="0 0 0" xyz="-0.016 0.012 -2.232e-4" />
            <inertia ixx="8.305e-5" ixy="1.465e-6" ixz="9.115e-7" iyy="1.066e-4" iyz="-5.222e-7" izz="9.683e-5" />
        </inertial>
    </link>
    <link name="link6">
        <visual>
            <geometry>
                <mesh filename="package://r_mini_description/meshes/link6.dae" />
            </geometry>
        </visual>
        <collision>
            <origin rpy="0 0 0" xyz="0 0 0" />
            <geometry>
                <mesh filename="package://r_mini_description/meshes/link6_collision.stl" />
            </geometry>
        </collision>
        <inertial>
            <mass value="0.022" />
            <origin rpy="0 0 0" xyz="-0.004  0.0531e-5 0.041" />
            <inertia ixx="9.537e-6" ixy="1.772e-8" ixz="2.429e-7" iyy="2.41e-6" iyz="-5.326e-9" izz="1.128e-5" />
        </inertial>
    </link>
    <joint name="joint0" type="fixed">
        <parent link="world" />
        <child link="base_link" />
        <origin rpy="0 0 0" xyz="0 0 0" />
    </joint>
    <joint name="joint1" type="revolute">
        <parent link="base_link" />
        <child link="link1" />
        <origin rpy="0 0 0" xyz="0 0 0.19360000" />
        <axis xyz="0 0 1" />
        <limit effort="500" lower="-3.14159265359" upper="3.14159265359" velocity="6.28318530718" />
        <dynamics damping="0" friction="0" />
    </joint>
    <joint name="joint2" type="revolute">
        <parent link="link1" />
        <child link="link2" />
        <origin rpy="-1.57079632679 0 0" xyz="0 0 0" />
        <axis xyz="0 0 1" />
        <limit effort="500" lower="0.0" upper="3.14159265359" velocity="6.28318530718" />
        <dynamics damping="0" friction="0" />
    </joint>
    <joint name="joint3" type="revolute">
        <parent link="link2" />
        <child link="link3" />
        <origin rpy="0 0 0" xyz="-0.37366195 0 0" />
        <axis xyz="0 0 1" />
        <limit effort="500" lower="-1.57079632679" upper="1.57079632679" velocity="6.28318530718" />
        <dynamics damping="0" friction="0" />
    </joint>
    <joint name="joint4" type="revolute">
        <parent link="link3" />
        <child link="link4" />
        <origin rpy="1.57079632679 0 0" xyz="-0.08 0 0" />
        <axis xyz="0 0 1" />
        <limit effort="500" lower="-3.14159265359" upper="3.14159265359" velocity="6.28318530718" />
        <dynamics damping="0" friction="0" />
    </joint>
    <joint name="joint5" type="revolute">
        <parent link="link4" />
        <child link="link5" />
        <origin rpy="-1.57079632679 0 0" xyz="0 0 0.39105000" />
        <axis xyz="0 0 1" />
        <limit effort="500" lower="1.57079632679" upper="4.71238898038" velocity="6.28318530718" />
        <dynamics damping="0" friction="0" />
    </joint>
    <joint name="joint6" type="revolute">
        <parent link="link5" />
        <child link="link6" />
        <origin rpy="-1.57079632679 0 0" xyz="0 0 0" />
        <axis xyz="0 0 1" />
        <limit effort="500" lower="-3.14159265359" upper="3.14159265359" velocity="6.28318530718" />
        <dynamics damping="0" friction="0" />
    </joint>
    <link name="link_effector" />
    <!--realsense_base link-->
    <!--use_nominal_extrinsics is set to true only during simulation or during when calibrated extrinsics are not being published-->
    <link name="realsense_base_link" />
    <material name="aluminum">
        <color rgba="0.5 0.5 0.5 1" />
    </material>
    <material name="plastic">
        <color rgba="0.1 0.1 0.1 1" />
    </material>
    <!-- camera body, with origin at bottom screw mount -->
    <joint name="camera_joint" type="fixed">
        <origin rpy="0 0 0" xyz="0 0 0" />
        <parent link="realsense_base_link" />
        <child link="camera_bottom_screw_frame" />
    </joint>
    <link name="camera_bottom_screw_frame" />
    <joint name="camera_link_joint" type="fixed">
        <origin rpy="0 0 0" xyz="0.0106 0.0175 0.0125" />
        <parent link="camera_bottom_screw_frame" />
        <child link="camera_link" />
    </joint>
    <link name="camera_link">
        <visual>
            <!-- the mesh origin is at front plate in between the two infrared camera axes -->
            <origin rpy="1.57079632679 0 1.57079632679" xyz="0.0043 -0.0175 0" />
            <geometry>
                <mesh filename="package://realsense2_description/meshes/d435_simplified.dae" />
            </geometry>
        </visual>
        <collision>
            <origin rpy="0 0 0" xyz="0 -0.0175 0" />
            <geometry>
                <box size="0.02505 0.09 0.025" />
            </geometry>
        </collision>
        <inertial>
            <!-- The following are not reliable values, and should not be used for modeling -->
            <mass value="0.074" />
            <origin xyz="0.002 0.002 0.013" rpy="0 0 0" />
            <inertia ixx="4.783e-5" ixy="3.111e-7" ixz="2.514e-8" iyy="7.104e-6" iyz="2.515e-8" izz="4.817e-5" />
        </inertial>
    </link>
    <!-- camera depth joints and links -->
    <joint name="camera_depth_joint" type="fixed">
        <origin rpy="0 0 0" xyz="0 0 0" />
        <parent link="camera_link" />
        <child link="camera_depth_frame" />
    </joint>
    <link name="camera_depth_frame" />
    <joint name="camera_depth_optical_joint" type="fixed">
        <origin rpy="-1.57079632679 0 -1.57079632679" xyz="0 0 0" />
        <parent link="camera_depth_frame" />
        <child link="camera_depth_optical_frame" />
    </joint>
    <link name="camera_depth_optical_frame" />
    <!-- camera left IR joints and links -->
    <joint name="camera_infra1_joint" type="fixed">
        <origin rpy="0 0 0" xyz="0 0.0 0" />
        <parent link="camera_link" />
        <child link="camera_infra1_frame" />
    </joint>
    <link name="camera_infra1_frame" />
    <joint name="camera_infra1_optical_joint" type="fixed">
        <origin rpy="-1.57079632679 0 -1.57079632679" xyz="0 0 0" />
        <parent link="camera_infra1_frame" />
        <child link="camera_infra1_optical_frame" />
    </joint>
    <link name="camera_infra1_optical_frame" />
    <!-- camera right IR joints and links -->
    <joint name="camera_infra2_joint" type="fixed">
        <origin rpy="0 0 0" xyz="0 -0.05 0" />
        <parent link="camera_link" />
        <child link="camera_infra2_frame" />
    </joint>
    <link name="camera_infra2_frame" />
    <joint name="camera_infra2_optical_joint" type="fixed">
        <origin rpy="-1.57079632679 0 -1.57079632679" xyz="0 0 0" />
        <parent link="camera_infra2_frame" />
        <child link="camera_infra2_optical_frame" />
    </joint>
    <link name="camera_infra2_optical_frame" />
    <!-- camera color joints and links -->
    <joint name="camera_color_joint" type="fixed">
        <origin rpy="0 0 0" xyz="0 0.015 0" />
        <parent link="camera_link" />
        <child link="camera_color_frame" />
    </joint>
    <link name="camera_color_frame" />
    <joint name="camera_color_optical_joint" type="fixed">
        <origin rpy="-1.57079632679 0 -1.57079632679" xyz="0 0 0" />
        <parent link="camera_color_frame" />
        <child link="camera_color_optical_frame" />
    </joint>
    <link name="camera_color_optical_frame" />
    <joint name="camera_usb_plug_joint" type="fixed">
        <origin rpy="0 0 0" xyz="-0.00605 -0.0528 0" />
        <parent link="camera_link" />
        <child link="camera_usb_plug_link" />
    </joint>
    <link name="camera_usb_plug_link">
        <visual>
            <!-- 0.044850 0.008000 0.018500 -->
            <origin rpy="0 0 1.57079632679" xyz="0. -0.022425 0." />
            <geometry>
                <!--box size="0.044850 0.008 0.0185" /-->
                <mesh filename="package://realsense2_description/meshes/plug.stl" />
            </geometry>
            <material name="plastic" />
        </visual>
        <collision>
            <origin rpy="0 0 1.57079632679" xyz="0. -0.022425 0." />
            <geometry>
                <!--box size="0.044850 0.008 0.0185" /-->
                <mesh filename="package://realsense2_description/meshes/plug_collision.stl" />
            </geometry>
        </collision>
        <inertial>
            <mass value="0.1" />
            <origin xyz="0 0 0" rpy="0 0 0" />
            <inertia ixx="0.03" iyy="0.03" izz="0.03" ixy="0.0" ixz="0.0" iyz="0.0" />
        </inertial>
    </link>
    <joint name="joint_effector" type="fixed">
        <parent link="link6" />
        <child link="link_effector" />
        <origin rpy="0 0 0" xyz="0 0 0.045" />
    </joint>
    <joint name="joint_realsense" type="fixed">
        <parent link="link_effector" />
        <child link="realsense_base_link" />
        <origin rpy="3.14159265359 -1.57079632679 0" xyz="-0.0125 0 0.01" />
    </joint>
    <gazebo>
        <plugin filename="libgazebo_ros_control.so" name="gazebo_ros_control">
            <robotNamespace>/</robotNamespace>
            <robotSimType>gazebo_ros_control/DefaultRobotHWSim</robotSimType>
        </plugin>
    </gazebo>
    <transmission name="trans1">
        <type>transmission_interface/SimpleTransmission</type>
        <joint name="joint1">
            <hardwareInterface>hardware_interface/PositionJointInterface</hardwareInterface>
        </joint>
        <actuator name="motor1">
            <hardwareInterface>hardware_interface/PositionJointInterface</hardwareInterface>
            <mechanicalReduction>1</mechanicalReduction>
        </actuator>
    </transmission>
    <transmission name="trans2">
        <type>transmission_interface/SimpleTransmission</type>
        <joint name="joint2">
            <hardwareInterface>hardware_interface/PositionJointInterface</hardwareInterface>
        </joint>
        <actuator name="motor2">
            <hardwareInterface>hardware_interface/PositionJointInterface</hardwareInterface>
            <mechanicalReduction>1</mechanicalReduction>
        </actuator>
    </transmission>
    <transmission name="trans2">
        <type>transmission_interface/SimpleTransmission</type>
        <joint name="joint2">
            <hardwareInterface>hardware_interface/PositionJointInterface</hardwareInterface>
        </joint>
        <actuator name="motor2">
            <hardwareInterface>hardware_interface/PositionJointInterface</hardwareInterface>
            <mechanicalReduction>1</mechanicalReduction>
        </actuator>
    </transmission>
    <transmission name="trans3">
        <type>transmission_interface/SimpleTransmission</type>
        <joint name="joint3">
            <hardwareInterface>hardware_interface/PositionJointInterface</hardwareInterface>
        </joint>
        <actuator name="motor3">
            <hardwareInterface>hardware_interface/PositionJointInterface</hardwareInterface>
            <mechanicalReduction>1</mechanicalReduction>
        </actuator>
    </transmission>
    <transmission name="trans4">
        <type>transmission_interface/SimpleTransmission</type>
        <joint name="joint4">
            <hardwareInterface>hardware_interface/PositionJointInterface</hardwareInterface>
        </joint>
        <actuator name="motor4">
            <hardwareInterface>hardware_interface/PositionJointInterface</hardwareInterface>
            <mechanicalReduction>1</mechanicalReduction>
        </actuator>
    </transmission>
    <transmission name="trans5">
        <type>transmission_interface/SimpleTransmission</type>
        <joint name="joint5">
            <hardwareInterface>hardware_interface/PositionJointInterface</hardwareInterface>
        </joint>
        <actuator name="motor5">
            <hardwareInterface>hardware_interface/PositionJointInterface</hardwareInterface>
            <mechanicalReduction>1</mechanicalReduction>
        </actuator>
    </transmission>
    <transmission name="trans6">
        <type>transmission_interface/SimpleTransmission</type>
        <joint name="joint6">
            <hardwareInterface>hardware_interface/PositionJointInterface</hardwareInterface>
        </joint>
        <actuator name="motor6">
            <hardwareInterface>hardware_interface/PositionJointInterface</hardwareInterface>
            <mechanicalReduction>1</mechanicalReduction>
        </actuator>
    </transmission>
</robot>

